2023-07-20 10:24:49,876 - __main__ - ERROR - An error occurred while processing https://codeforces.com/contest/1164/problem/F: Failed to access https://codeforces.com/contest/1164/problem/F
Traceback (most recent call last):
  File "crawl_problems.py", line 45, in make_request
    response.raise_for_status()
  File "/home/kita456/projects/Codeforces_Problems_daily_update/.venv/lib/python3.8/site-packages/requests/models.py", line 1021, in raise_for_status
    raise HTTPError(http_error_msg, response=self)
requests.exceptions.HTTPError: 500 Server Error: Internal Server Error for url: https://codeforces.com/contest/1164/problem/F

The above exception was the direct cause of the following exception:

Traceback (most recent call last):
  File "crawl_problems.py", line 168, in get_problem_info
    response = make_request(problem_url)
  File "crawl_problems.py", line 47, in make_request
    raise Exception(f"Failed to access {url}") from e
Exception: Failed to access https://codeforces.com/contest/1164/problem/F
2023-07-20 10:24:53,610 - __main__ - ERROR - An error occurred while processing https://codeforces.com/contest/1164/problem/H: Failed to access https://codeforces.com/contest/1164/problem/H
Traceback (most recent call last):
  File "crawl_problems.py", line 45, in make_request
    response.raise_for_status()
  File "/home/kita456/projects/Codeforces_Problems_daily_update/.venv/lib/python3.8/site-packages/requests/models.py", line 1021, in raise_for_status
    raise HTTPError(http_error_msg, response=self)
requests.exceptions.HTTPError: 500 Server Error: Internal Server Error for url: https://codeforces.com/contest/1164/problem/H

The above exception was the direct cause of the following exception:

Traceback (most recent call last):
  File "crawl_problems.py", line 168, in get_problem_info
    response = make_request(problem_url)
  File "crawl_problems.py", line 47, in make_request
    raise Exception(f"Failed to access {url}") from e
Exception: Failed to access https://codeforces.com/contest/1164/problem/H
2023-07-20 10:24:57,245 - __main__ - ERROR - An error occurred while processing https://codeforces.com/contest/1164/problem/J: Failed to access https://codeforces.com/contest/1164/problem/J
Traceback (most recent call last):
  File "crawl_problems.py", line 45, in make_request
    response.raise_for_status()
  File "/home/kita456/projects/Codeforces_Problems_daily_update/.venv/lib/python3.8/site-packages/requests/models.py", line 1021, in raise_for_status
    raise HTTPError(http_error_msg, response=self)
requests.exceptions.HTTPError: 500 Server Error: Internal Server Error for url: https://codeforces.com/contest/1164/problem/J

The above exception was the direct cause of the following exception:

Traceback (most recent call last):
  File "crawl_problems.py", line 168, in get_problem_info
    response = make_request(problem_url)
  File "crawl_problems.py", line 47, in make_request
    raise Exception(f"Failed to access {url}") from e
Exception: Failed to access https://codeforces.com/contest/1164/problem/J
2023-07-20 10:25:03,182 - __main__ - ERROR - An error occurred while processing https://codeforces.com/contest/1164/problem/L: Failed to access https://codeforces.com/contest/1164/problem/L
Traceback (most recent call last):
  File "crawl_problems.py", line 45, in make_request
    response.raise_for_status()
  File "/home/kita456/projects/Codeforces_Problems_daily_update/.venv/lib/python3.8/site-packages/requests/models.py", line 1021, in raise_for_status
    raise HTTPError(http_error_msg, response=self)
requests.exceptions.HTTPError: 500 Server Error: Internal Server Error for url: https://codeforces.com/contest/1164/problem/L

The above exception was the direct cause of the following exception:

Traceback (most recent call last):
  File "crawl_problems.py", line 168, in get_problem_info
    response = make_request(problem_url)
  File "crawl_problems.py", line 47, in make_request
    raise Exception(f"Failed to access {url}") from e
Exception: Failed to access https://codeforces.com/contest/1164/problem/L
2023-07-20 10:25:04,859 - __main__ - ERROR - An error occurred while processing https://codeforces.com/contest/1164/problem/M: Failed to access https://codeforces.com/contest/1164/problem/M
Traceback (most recent call last):
  File "crawl_problems.py", line 45, in make_request
    response.raise_for_status()
  File "/home/kita456/projects/Codeforces_Problems_daily_update/.venv/lib/python3.8/site-packages/requests/models.py", line 1021, in raise_for_status
    raise HTTPError(http_error_msg, response=self)
requests.exceptions.HTTPError: 500 Server Error: Internal Server Error for url: https://codeforces.com/contest/1164/problem/M

The above exception was the direct cause of the following exception:

Traceback (most recent call last):
  File "crawl_problems.py", line 168, in get_problem_info
    response = make_request(problem_url)
  File "crawl_problems.py", line 47, in make_request
    raise Exception(f"Failed to access {url}") from e
Exception: Failed to access https://codeforces.com/contest/1164/problem/M
2023-07-20 10:25:08,609 - __main__ - ERROR - An error occurred while processing https://codeforces.com/contest/1164/problem/O: Failed to access https://codeforces.com/contest/1164/problem/O
Traceback (most recent call last):
  File "crawl_problems.py", line 45, in make_request
    response.raise_for_status()
  File "/home/kita456/projects/Codeforces_Problems_daily_update/.venv/lib/python3.8/site-packages/requests/models.py", line 1021, in raise_for_status
    raise HTTPError(http_error_msg, response=self)
requests.exceptions.HTTPError: 500 Server Error: Internal Server Error for url: https://codeforces.com/contest/1164/problem/O

The above exception was the direct cause of the following exception:

Traceback (most recent call last):
  File "crawl_problems.py", line 168, in get_problem_info
    response = make_request(problem_url)
  File "crawl_problems.py", line 47, in make_request
    raise Exception(f"Failed to access {url}") from e
Exception: Failed to access https://codeforces.com/contest/1164/problem/O
2023-07-20 10:25:16,392 - __main__ - ERROR - An error occurred while processing https://codeforces.com/contest/1164/problem/R: Failed to access https://codeforces.com/contest/1164/problem/R
Traceback (most recent call last):
  File "crawl_problems.py", line 45, in make_request
    response.raise_for_status()
  File "/home/kita456/projects/Codeforces_Problems_daily_update/.venv/lib/python3.8/site-packages/requests/models.py", line 1021, in raise_for_status
    raise HTTPError(http_error_msg, response=self)
requests.exceptions.HTTPError: 500 Server Error: Internal Server Error for url: https://codeforces.com/contest/1164/problem/R

The above exception was the direct cause of the following exception:

Traceback (most recent call last):
  File "crawl_problems.py", line 168, in get_problem_info
    response = make_request(problem_url)
  File "crawl_problems.py", line 47, in make_request
    raise Exception(f"Failed to access {url}") from e
Exception: Failed to access https://codeforces.com/contest/1164/problem/R
2023-07-20 10:25:20,283 - __main__ - ERROR - An error occurred while processing https://codeforces.com/contest/1164/problem/T: Failed to access https://codeforces.com/contest/1164/problem/T
Traceback (most recent call last):
  File "crawl_problems.py", line 45, in make_request
    response.raise_for_status()
  File "/home/kita456/projects/Codeforces_Problems_daily_update/.venv/lib/python3.8/site-packages/requests/models.py", line 1021, in raise_for_status
    raise HTTPError(http_error_msg, response=self)
requests.exceptions.HTTPError: 500 Server Error: Internal Server Error for url: https://codeforces.com/contest/1164/problem/T

The above exception was the direct cause of the following exception:

Traceback (most recent call last):
  File "crawl_problems.py", line 168, in get_problem_info
    response = make_request(problem_url)
  File "crawl_problems.py", line 47, in make_request
    raise Exception(f"Failed to access {url}") from e
Exception: Failed to access https://codeforces.com/contest/1164/problem/T
2023-07-20 11:21:01,798 - __main__ - ERROR - An error occurred while processing https://codeforces.com/contest/936/problem/E: Failed to access https://codeforces.com/contest/936/problem/E
Traceback (most recent call last):
  File "crawl_problems.py", line 45, in make_request
    response.raise_for_status()
  File "/home/kita456/projects/Codeforces_Problems_daily_update/.venv/lib/python3.8/site-packages/requests/models.py", line 1021, in raise_for_status
    raise HTTPError(http_error_msg, response=self)
requests.exceptions.HTTPError: 524 Server Error:  for url: https://codeforces.com/contest/936/problem/E

The above exception was the direct cause of the following exception:

Traceback (most recent call last):
  File "crawl_problems.py", line 168, in get_problem_info
    response = make_request(problem_url)
  File "crawl_problems.py", line 47, in make_request
    raise Exception(f"Failed to access {url}") from e
Exception: Failed to access https://codeforces.com/contest/936/problem/E
